<?xml version="1.0" encoding="UTF-8"?>
<robot name="Robot">
    <link name="base_link">
        <inertial>
            <mass value="0"/>
            <inertia ixx="0" ixy="0" ixz="0" iyy="0" iyz="0" izz="0"/>
        </inertial>
        <visual>
            <origin rpy="0.00000000 0.00000000 0.00000000" xyz="0.00000000 0.00000000 0.00000000"/>
            <geometry>
                <mesh filename="meshes\visual\base_link.stl" scale="1.00000000 1.00000000 1.00000000"/>
            </geometry>
            <material name="">
                <color rgba="1.00000000 0.43000000 0.00000000 1.00000000"/>
            </material>
        </visual>
        <collision>
            <origin rpy="0.00000000 0.00000000 0.00000000" xyz="0.00000000 0.00000000 0.00000000"/>
            <geometry>
                <mesh filename="meshes\collision\base_link.stl" scale="1.00000000 1.00000000 1.00000000"/>
            </geometry>
        </collision>
    </link>
    <link name="link_1">
        <inertial>
            <origin rpy="0.00000000 0.00000000 0.00000000" xyz="0.00000000 0.00000000 0.00000000"/>
            <mass value="0.00000000"/>
            <inertia ixx="0.00000000" ixy="0.00000000" ixz="0.00000000" iyy="0.00000000" iyz="0.00000000" izz="0.00000000"/>
        </inertial>
        <visual>
            <origin rpy="0.00000000 0.00000000 0.00000000" xyz="0.00000000 0.00000000 0.00000000"/>
            <geometry>
                <mesh filename="meshes\visual\link_1.stl" scale="1.00000000 1.00000000 1.00000000"/>
            </geometry>
            <material name="">
                <color rgba="0.50000000 0.50000000 0.50000000 1.00000000"/>
            </material>
        </visual>
        <collision>
            <origin rpy="0.00000000 0.00000000 0.00000000" xyz="0.00000000 0.00000000 0.00000000"/>
            <geometry>
                <mesh filename="meshes\collision\link_1.stl" scale="1.00000000 1.00000000 1.00000000"/>
            </geometry>
        </collision>
    </link>
    <link name="link_2">
        <inertial>
            <origin rpy="0.00000000 0.00000000 0.00000000" xyz="0.00000000 0.00000000 0.00000000"/>
            <mass value="0.00000000"/>
            <inertia ixx="0.00000000" ixy="0.00000000" ixz="0.00000000" iyy="0.00000000" iyz="0.00000000" izz="0.00000000"/>
        </inertial>
        <visual>
            <origin rpy="0.00000000 0.00000000 0.00000000" xyz="0.00000000 0.00000000 0.00000000"/>
            <geometry>
                <mesh filename="meshes\visual\link_2.stl" scale="1.00000000 1.00000000 1.00000000"/>
            </geometry>
            <material name="">
                <color rgba="0.50000000 0.50000000 0.50000000 1.00000000"/>
            </material>
        </visual>
        <collision>
            <origin rpy="0.00000000 0.00000000 0.00000000" xyz="0.00000000 0.00000000 0.00000000"/>
            <geometry>
                <mesh filename="meshes\collision\link_2.stl" scale="1.00000000 1.00000000 1.00000000"/>
            </geometry>
        </collision>
    </link>
    <link name="link_3">
        <inertial>
            <origin rpy="0.00000000 0.00000000 0.00000000" xyz="0.00000000 0.00000000 0.00000000"/>
            <mass value="0.00000000"/>
            <inertia ixx="0.00000000" ixy="0.00000000" ixz="0.00000000" iyy="0.00000000" iyz="0.00000000" izz="0.00000000"/>
        </inertial>
        <visual>
            <origin rpy="0.00000000 0.00000000 0.00000000" xyz="0.00000000 0.00000000 0.00000000"/>
            <geometry>
                <mesh filename="meshes\visual\link_3.stl" scale="1.00000000 1.00000000 1.00000000"/>
            </geometry>
            <material name="">
                <color rgba="0.50000000 0.50000000 0.50000000 1.00000000"/>
            </material>
        </visual>
        <collision>
            <origin rpy="0.00000000 0.00000000 0.00000000" xyz="0.00000000 0.00000000 0.00000000"/>
            <geometry>
                <mesh filename="meshes\collision\link_3.stl" scale="1.00000000 1.00000000 1.00000000"/>
            </geometry>
        </collision>
    </link>
    <link name="link_4">
        <inertial>
            <origin rpy="0.00000000 0.00000000 0.00000000" xyz="0.00000000 0.00000000 0.00000000"/>
            <mass value="0.00000000"/>
            <inertia ixx="0.00000000" ixy="0.00000000" ixz="0.00000000" iyy="0.00000000" iyz="0.00000000" izz="0.00000000"/>
        </inertial>
        <visual>
            <origin rpy="0.00000000 0.00000000 0.00000000" xyz="0.00000000 0.00000000 0.00000000"/>
            <geometry>
                <mesh filename="meshes\visual\link_4.stl" scale="1.00000000 1.00000000 1.00000000"/>
            </geometry>
            <material name="">
                <color rgba="0.50000000 0.50000000 0.50000000 1.00000000"/>
            </material>
        </visual>
        <collision>
            <origin rpy="0.00000000 0.00000000 0.00000000" xyz="0.00000000 0.00000000 0.00000000"/>
            <geometry>
                <mesh filename="meshes\collision\link_4.stl" scale="1.00000000 1.00000000 1.00000000"/>
            </geometry>
        </collision>
    </link>
    <link name="link_5">
        <inertial>
            <origin rpy="0.00000000 0.00000000 0.00000000" xyz="0.00000000 0.00000000 0.00000000"/>
            <mass value="0.00000000"/>
            <inertia ixx="0.00000000" ixy="0.00000000" ixz="0.00000000" iyy="0.00000000" iyz="0.00000000" izz="0.00000000"/>
        </inertial>
        <visual>
            <origin rpy="0.00000000 0.00000000 0.00000000" xyz="0.00000000 0.00000000 0.00000000"/>
            <geometry>
                <mesh filename="meshes\visual\link_5.stl" scale="1.00000000 1.00000000 1.00000000"/>
            </geometry>
            <material name="">
                <color rgba="0.50000000 0.50000000 0.50000000 1.00000000"/>
            </material>
        </visual>
        <collision>
            <origin rpy="0.00000000 0.00000000 0.00000000" xyz="0.00000000 0.00000000 0.00000000"/>
            <geometry>
                <mesh filename="meshes\collision\link_5.stl" scale="1.00000000 1.00000000 1.00000000"/>
            </geometry>
        </collision>
    </link>
    <link name="link_6">
        <inertial>
            <origin rpy="0.00000000 0.00000000 0.00000000" xyz="0.00000000 0.00000000 0.00000000"/>
            <mass value="0.00000000"/>
            <inertia ixx="0.00000000" ixy="0.00000000" ixz="0.00000000" iyy="0.00000000" iyz="0.00000000" izz="0.00000000"/>
        </inertial>
        <visual>
            <origin rpy="0.00000000 0.00000000 0.00000000" xyz="0.00000000 0.00000000 0.00000000"/>
            <geometry>
                <mesh filename="meshes\visual\link_6.stl" scale="1.00000000 1.00000000 1.00000000"/>
            </geometry>
            <material name="">
                <color rgba="0.50000000 0.50000000 0.50000000 1.00000000"/>
            </material>
        </visual>
        <collision>
            <origin rpy="0.00000000 0.00000000 0.00000000" xyz="0.00000000 0.00000000 0.00000000"/>
            <geometry>
                <mesh filename="meshes\collision\link_6.stl" scale="1.00000000 1.00000000 1.00000000"/>
            </geometry>
        </collision>
    </link>
    <link name="tool0">
        <inertial>
            <origin rpy="0.00000000 0.00000000 0.00000000" xyz="0.00000000 0.00000000 0.00000000"/>
            <mass value="0.00000000"/>
            <inertia ixx="0.00000000" ixy="0.00000000" ixz="0.00000000" iyy="0.00000000" iyz="0.00000000" izz="0.00000000"/>
        </inertial>
    </link>
    <joint name="joint_1" type="revolute">
        <parent link="base_link"/>
        <child link="link_1"/>
        <origin rpy="0.00000000 0.00000000 0.00000000" xyz="0.00000000 0.00000000 0.00000000"/>
        <axis xyz="0.00000000 0.00000000 1.00000000"/>
        <limit lower="-3.14159265" upper="3.14159265" effort="0" velocity="0"/>
    </joint>
    <joint name="joint_2" type="revolute">
        <parent link="link_1"/>
        <child link="link_2"/>
        <origin rpy="0.00000000 0.00000000 0.00000000" xyz="0.15000000 0.00000000 0.48650000"/>
        <axis xyz="0.00000000 1.00000000 0.00000000"/>
        <limit lower="-1.09950000" upper="1.91980000" effort="0" velocity="0"/>
    </joint>
    <joint name="joint_3" type="revolute">
        <parent link="link_2"/>
        <child link="link_3"/>
        <origin rpy="0.00000000 0.00000000 0.00000000" xyz="0.00000000 0.00000000 0.47500000"/>
        <axis xyz="0.00000000 1.00000000 0.00000000"/>
        <limit lower="-4.10150000" upper="0.95990000" effort="0" velocity="0"/>
    </joint>
    <joint name="joint_4" type="revolute">
        <parent link="link_3"/>
        <child link="link_4"/>
        <origin rpy="0.00000000 0.00000000 0.00000000" xyz="0.30000000 0.00000000 0.00000000"/>
        <axis xyz="1.00000000 0.00000000 0.00000000"/>
        <limit lower="-3.49060000" upper="3.49060000" effort="0" velocity="0"/>
    </joint>
    <joint name="joint_5" type="revolute">
        <parent link="link_4"/>
        <child link="link_5"/>
        <origin rpy="0.00000000 0.00000000 0.00000000" xyz="0.30000000 0.00000000 0.00000000"/>
        <axis xyz="0.00000000 1.00000000 0.00000000"/>
        <limit lower="-2.00710000" upper="2.00710000" effort="0" velocity="0"/>
    </joint>
    <joint name="joint_6" type="revolute">
        <parent link="link_5"/>
        <child link="link_6"/>
        <origin rpy="0.00000000 0.00000000 0.00000000" xyz="0.06500000 0.00000000 0.00000000"/>
        <axis xyz="1.00000000 0.00000000 0.00000000"/>
        <limit lower="-6.98130000" upper="6.98130000" effort="0" velocity="0"/>
    </joint>
    <joint name="joint_6-tool0" type="fixed">
        <parent link="link_6"/>
        <child link="tool0"/>
        <origin rpy="0.00000000 1.57079633 0.00000000" xyz="0.00000000 0.00000000 0.00000000"/>
        <axis xyz="100"/>
    </joint>
</robot>
